Workbook
Name Excel_BuiltIn__FilterDatabase: Formulario!$Q$31:$Q$34
Name Print_Area: Formulario!$B$1:$K$80
Name Print_Area: Tecnicas!$A$1:$D$59
Name Print_Titles: Tecnicas!$1:$4

Sheet Formulario
D1: FORMULARIO DE EVALUACIÓN DEL DESEMPEÑO 2025
B2: UNIDAD ADMINISTRATIVA | C2: =IF(C4=0," ",VLOOKUP(C4,'[1]Formato Asignación de funciones'!B1:K416,3,0))
B3: APELLIDOS Y NOMBRES DEL SERVIDOR (EVALUADO) | C3: =IF(C4=0," ",VLOOKUP(C4,'[1]Formato Asignación de funciones'!B1:K416,2,0)) | F3: DENOMINACIÓN DEL PUESTO INSTITUCIONAL
B4: No. CEDULA DEL EVALUADO | F4: TÍTULO O PROFESIÓN:
B5: FECHA DEL FORMULARIO | F5: APELLIDOS Y NOMBRES DEL JEFE INMEDIATO (EVALUADOR)
B6: PERÍODO DESDE: | C6: =IF(C4=0," ",VLOOKUP(C4,'[1]Formato Asignación de funciones'!B1:K416,8,0)) | D6: 45323 | F6: HASTA: | H6: 45657
B7: EVALUACIÓN DE LAS ACTIVIDADES DEL PUESTO
B8: INDICADORES DE GESTIÓN DEL PUESTO: | E8: # Actividades: | F8: =M9 -> 0 | G8: Factor: | H8: 0.6 | L8: VALOR FACTOR | M8: NUMERO ACTIVIDADES
B9: Descripción de Actividades | D9: Indicador | F9: Meta del Período Evaluado (número) | G9: Cumplidos | H9: % de Cumplimiento | J9: Nivel de Cumplimiento | L9: =SUM(L10:L14) -> 0 | M9: =SUM(M10:M14) -> 0 | N9: X | O9: Y | R9: =SUM(R10:R14) -> 0
H10: =IF(OR(G10<0,G10="",F10=""),"",IF(AND(G10>F10),100,(G10*100/F10))) | J10: =IF(OR(H10="",H10<0),"",IF(H10>=90.5,5,IF(AND(H10>=80.5,H10<=90.4),4,IF(AND(H10>=70.5,H10<=80.4),3,IF(AND(H10>=60.5,H10<=70.4),2,IF(H10<=60.4,1,"")))))) | K10: =IF(OR(H10="",H10<0),"",IF(H10>=90.5,5,IF(AND(H10>=80.5,H10<=90.4),4,IF(AND(H10>=70.5,H10<=80.4),3,IF(AND(H10>=60.5,H10<=70.4),2,IF(H10<=60.4,1,"")))))) | L10: =IF(J10<>"",IF(J10=5,60,IF(J10=4,45,IF(J10=3,30,IF(J10=2,15,IF(J10=1,0,""))))),0) -> 0 | M10: =IF(AND(B10<>"",D10<>"",F10<>""),1,0) -> 0 | N10: =IF(AND(F10<>"",G10<>""),1,0) -> 0 | O10: =IF(AND(G10>=F10,N10=1),1,0) -> 0 | P10: 0 | Q10: =IF(OR(G10<0,G10="",F10=""),"",IF(AND(G10>F10),1,0)) | R10: =IF(L10=0,0,(L10/M9)) -> 0
H11: =IF(OR(G11<0,G11="",F11=""),"",IF(AND(G11>F11),100,(G11*100/F11))) | J11: =IF(OR(H11="",H11<0),"",IF(H11>=90.5,5,IF(AND(H11>=80.5,H11<=90.4),4,IF(AND(H11>=70.5,H11<=80.4),3,IF(AND(H11>=60.5,H11<=70.4),2,IF(H11<=60.4,1,"")))))) | K11: =IF(OR(H11="",H11<0),"",IF(H11>=90.5,5,IF(AND(H11>=80.5,H11<=90.4),4,IF(AND(H11>=70.5,H11<=80.4),3,IF(AND(H11>=60.5,H11<=70.4),2,IF(H11<=60.4,1,"")))))) | L11: =IF(J11<>"",IF(J11=5,60,IF(J11=4,45,IF(J11=3,30,IF(J11=2,15,IF(J11=1,0,""))))),0) -> 0 | M11: =IF(AND(B11<>"",D11<>"",F11<>""),1,0) -> 0 | N11: =IF(AND(F11<>"",G11<>""),1,0) -> 0 | O11: =IF(AND(G11>=F11,N11=1),1,0) -> 0 | P11: 0 | Q11: =IF(OR(G11<0,G11="",F11=""),"",IF(AND(G11>F11),1,0)) | R11: =IF(L11=0,0,(L11/M9)) -> 0
H12: =IF(OR(G12<0,G12="",F12=""),"",IF(AND(G12>F12),100,(G12*100/F12))) | J12: =IF(OR(H12="",H12<0),"",IF(H12>=90.5,5,IF(AND(H12>=80.5,H12<=90.4),4,IF(AND(H12>=70.5,H12<=80.4),3,IF(AND(H12>=60.5,H12<=70.4),2,IF(H12<=60.4,1,"")))))) | K12: =IF(OR(H12="",H12<0),"",IF(H12>=90.5,5,IF(AND(H12>=80.5,H12<=90.4),4,IF(AND(H12>=70.5,H12<=80.4),3,IF(AND(H12>=60.5,H12<=70.4),2,IF(H12<=60.4,1,"")))))) | L12: =IF(J12<>"",IF(J12=5,60,IF(J12=4,45,IF(J12=3,30,IF(J12=2,15,IF(J12=1,0,""))))),0) -> 0 | M12: =IF(AND(B12<>"",D12<>"",F12<>""),1,0) -> 0 | N12: =IF(AND(F12<>"",G12<>""),1,0) -> 0 | O12: =IF(AND(G12>=F12,N12=1),1,0) -> 0 | P12: 0 | Q12: =IF(OR(G12<0,G12="",F12=""),"",IF(AND(G12>F12),1,0)) | R12: =IF(L12=0,0,(L12/M9)) -> 0
H13: =IF(OR(G13<0,G13="",F13=""),"",IF(AND(G13>F13),100,(G13*100/F13))) | J13: =IF(OR(H13="",H13<0),"",IF(H13>=90.5,5,IF(AND(H13>=80.5,H13<=90.4),4,IF(AND(H13>=70.5,H13<=80.4),3,IF(AND(H13>=60.5,H13<=70.4),2,IF(H13<=60.4,1,"")))))) | K13: =IF(OR(H13="",H13<0),"",IF(H13>=90.5,5,IF(AND(H13>=80.5,H13<=90.4),4,IF(AND(H13>=70.5,H13<=80.4),3,IF(AND(H13>=60.5,H13<=70.4),2,IF(H13<=60.4,1,"")))))) | L13: =IF(J13<>"",IF(J13=5,60,IF(J13=4,45,IF(J13=3,30,IF(J13=2,15,IF(J13=1,0,""))))),0) -> 0 | M13: =IF(AND(B13<>"",D13<>"",F13<>""),1,0) -> 0 | N13: =IF(AND(F13<>"",G13<>""),1,0) -> 0 | O13: =IF(AND(G13>=F13,N13=1),1,0) -> 0 | P13: 0 | Q13: =IF(OR(G13<0,G13="",F13=""),"",IF(AND(G13>F13),1,0)) | R13: =IF(L13=0,0,(L13/M9)) -> 0
H14: =IF(OR(G14<0,G14="",F14=""),"",IF(AND(G14>F14),100,(G14*100/F14))) | J14: =IF(OR(H14="",H14<0),"",IF(H14>=90.5,5,IF(AND(H14>=80.5,H14<=90.4),4,IF(AND(H14>=70.5,H14<=80.4),3,IF(AND(H14>=60.5,H14<=70.4),2,IF(H14<=60.4,1,"")))))) | K14: =IF(OR(H14="",H14<0),"",IF(H14>=90.5,5,IF(AND(H14>=80.5,H14<=90.4),4,IF(AND(H14>=70.5,H14<=80.4),3,IF(AND(H14>=60.5,H14<=70.4),2,IF(H14<=60.4,1,"")))))) | L14: =IF(J14<>"",IF(J14=5,60,IF(J14=4,45,IF(J14=3,30,IF(J14=2,15,IF(J14=1,0,""))))),0) -> 0 | M14: =IF(AND(B14<>"",D14<>"",F14<>""),1,0) -> 0 | N14: =IF(AND(F14<>"",G14<>""),1,0) -> 0 | O14: =IF(AND(G14>=F14,N14=1),1,0) -> 0 | P14: 0 | Q14: =IF(OR(G14<0,G14="",F14=""),"",IF(AND(G14>F14),1,0)) | R14: =IF(L14=0,0,(L14/M9)) -> 0
B15: Total Actividades Esenciales: | J15: =CONCATENATE(ROUND(R9,1),"%") -> 0%
B16: CONOCIMIENTOS | C16: # Conocimientos: | E16: =M16 -> 0 | F16: Factor: | G16: 0.08 | H16: Nivel requerido | K16: Nivel observado | L16: =SUM(L17:L22) -> 0 | M16: =SUM(M17:M22) -> 0 | N16: =SUM(N17:N22) -> 0
I17: =IF(B17="","",IF(H17="Sobresaliente",5,IF(H17="Muy Bueno",4,IF(H17="Bueno",3,IF(H17="Regular",2,IF(H17="Insuficiente",1,"")))))) | J17: =IF(B17="","",IF(K17="Sobresaliente",5,IF(K17="Muy Bueno",4,IF(K17="Bueno",3,IF(K17="Regular",2,IF(K17="Insuficiente",1,"")))))) | L17: =IF(J17<>"",IF(J17=1,0,IF(J17=1,0,IF(I17<=J17,8,IF(I17-J17=1,6,IF(I17-J17=2,4,IF(I17-J17=3,2,0)))))),0) -> 0 | M17: =IF(B17<>"",1,0) -> 0 | N17: =IF(L17=0,0,(L17/M16)) -> 0
I18: =IF(B18="","",IF(H18="Sobresaliente",5,IF(H18="Muy Bueno",4,IF(H18="Bueno",3,IF(H18="Regular",2,IF(H18="Insuficiente",1,"")))))) | J18: =IF(B18="","",IF(K18="Sobresaliente",5,IF(K18="Muy Bueno",4,IF(K18="Bueno",3,IF(K18="Regular",2,IF(K18="Insuficiente",1,"")))))) | L18: =IF(J18<>"",IF(J18=1,0,IF(J18=1,0,IF(I18<=J18,8,IF(I18-J18=1,6,IF(I18-J18=2,4,IF(I18-J18=3,2,0)))))),0) -> 0 | M18: =IF(B18<>"",1,0) -> 0 | N18: =IF(L18=0,0,(L18/M16)) -> 0
I19: =IF(B19="","",IF(H19="Sobresaliente",5,IF(H19="Muy Bueno",4,IF(H19="Bueno",3,IF(H19="Regular",2,IF(H19="Insuficiente",1,"")))))) | J19: =IF(B19="","",IF(K19="Sobresaliente",5,IF(K19="Muy Bueno",4,IF(K19="Bueno",3,IF(K19="Regular",2,IF(K19="Insuficiente",1,"")))))) | L19: =IF(J19<>"",IF(J19=1,0,IF(J19=1,0,IF(I19<=J19,8,IF(I19-J19=1,6,IF(I19-J19=2,4,IF(I19-J19=3,2,0)))))),0) -> 0 | M19: =IF(B19<>"",1,0) -> 0 | N19: =IF(L19=0,0,(L19/M16)) -> 0
I20: =IF(B20="","",IF(H20="Sobresaliente",5,IF(H20="Muy Bueno",4,IF(H20="Bueno",3,IF(H20="Regular",2,IF(H20="Insuficiente",1,"")))))) | J20: =IF(B20="","",IF(K20="Sobresaliente",5,IF(K20="Muy Bueno",4,IF(K20="Bueno",3,IF(K20="Regular",2,IF(K20="Insuficiente",1,"")))))) | L20: =IF(J20<>"",IF(J20=1,0,IF(J20=1,0,IF(I20<=J20,8,IF(I20-J20=1,6,IF(I20-J20=2,4,IF(I20-J20=3,2,0)))))),0) -> 0 | M20: =IF(B20<>"",1,0) -> 0 | N20: =IF(L20=0,0,(L20/M16)) -> 0
I21: =IF(B21="","",IF(H21="Sobresaliente",5,IF(H21="Muy Bueno",4,IF(H21="Bueno",3,IF(H21="Regular",2,IF(H21="Insuficiente",1,"")))))) | J21: =IF(B21="","",IF(K21="Sobresaliente",5,IF(K21="Muy Bueno",4,IF(K21="Bueno",3,IF(K21="Regular",2,IF(K21="Insuficiente",1,"")))))) | L21: =IF(J21<>"",IF(J21=1,0,IF(J21=1,0,IF(I21<=J21,8,IF(I21-J21=1,6,IF(I21-J21=2,4,IF(I21-J21=3,2,0)))))),0) -> 0 | M21: =IF(B21<>"",1,0) -> 0 | N21: =IF(L21=0,0,(L21/M16)) -> 0
I22: =IF(B22="","",IF(H22="Sobresaliente",5,IF(H22="Muy Bueno",4,IF(H22="Bueno",3,IF(H22="Regular",2,IF(H22="Insuficiente",1,"")))))) | J22: =IF(B22="","",IF(K22="Sobresaliente",5,IF(K22="Muy Bueno",4,IF(K22="Bueno",3,IF(K22="Regular",2,IF(K22="Insuficiente",1,"")))))) | L22: =IF(J22<>"",IF(J22=1,0,IF(J22=1,0,IF(I22<=J22,8,IF(I22-J22=1,6,IF(I22-J22=2,4,IF(I22-J22=3,2,0)))))),0) -> 0 | M22: =IF(B22<>"",1,0) -> 0 | N22: =IF(L22=0,0,(L22/M16)) -> 0
B23: Total Conocimientos: | K23: =CONCATENATE(ROUND(N16,1),"%") -> 0%
B24: COMPETENCIAS TÉCNICAS DEL PUESTO | D24: # Competencias: | F24: =M24 -> 0 | G24: Factor: | H24: 0.08 | L24: =IF(M24=F24,SUM(L26:L30),0%) -> 0 | M24: =SUM(M26:M30) -> 0 | N24: =SUM(N26:N30) -> 0
B25: DESTREZAS | D25: Relevancia | F25: Comportamiento Observable | J25: Nivel de Desarrollo
F26: =IF(AND(B26<>"",D26<>""),IF(D26="Alta",VLOOKUP(B26,Tecnicas!$A$5:$D$58,2,0),IF(D26="Media",VLOOKUP(B26,Tecnicas!$A$5:$D$58,3,0),IF(D26="Baja",VLOOKUP(B26,Tecnicas!A4:D58,4,0)))),"") | J26: =IF(OR(B26="",D26=""),"",IF(K26="Altamente Desarrollada",5,IF(K26="Desarrollada",4,IF(K26="Medianamente Desarrollada",3,IF(K26="Poco Desarrollada",2,IF(K26="No Desarrollada",1,"")))))) | L26: =IF(J26<>"",IF(J26=5,8,IF(J26=4,6,IF(J26=3,4,IF(J26=2,2,IF(J26=1,0,""))))),0) -> 0 | M26: =IF(AND(B26<>"",D26<>"",K26<>""),1,0) -> 0 | N26: =IF(L26=0,0,(L26/M24)) -> 0
F27: =IF(AND(B27<>"",D27<>""),IF(D27="Alta",VLOOKUP(B27,Tecnicas!$A$5:$D$58,2,0),IF(D27="Media",VLOOKUP(B27,Tecnicas!$A$5:$D$58,3,0),IF(D27="Baja",VLOOKUP(B27,Tecnicas!A5:D59,4,0)))),"") | J27: =IF(OR(B27="",D27=""),"",IF(K27="Altamente Desarrollada",5,IF(K27="Desarrollada",4,IF(K27="Medianamente Desarrollada",3,IF(K27="Poco Desarrollada",2,IF(K27="No Desarrollada",1,"")))))) | L27: =IF(J27<>"",IF(J27=5,8,IF(J27=4,6,IF(J27=3,4,IF(J27=2,2,IF(J27=1,0,""))))),0) -> 0 | M27: =IF(AND(B27<>"",D27<>"",K27<>""),1,0) -> 0 | N27: =IF(L27=0,0,(L27/M24)) -> 0
F28: =IF(AND(B28<>"",D28<>""),IF(D28="Alta",VLOOKUP(B28,Tecnicas!$A$5:$D$58,2,0),IF(D28="Media",VLOOKUP(B28,Tecnicas!$A$5:$D$58,3,0),IF(D28="Baja",VLOOKUP(B28,Tecnicas!A6:D60,4,0)))),"") | J28: =IF(OR(B28="",D28=""),"",IF(K28="Altamente Desarrollada",5,IF(K28="Desarrollada",4,IF(K28="Medianamente Desarrollada",3,IF(K28="Poco Desarrollada",2,IF(K28="No Desarrollada",1,"")))))) | L28: =IF(J28<>"",IF(J28=5,8,IF(J28=4,6,IF(J28=3,4,IF(J28=2,2,IF(J28=1,0,""))))),0) -> 0 | M28: =IF(AND(B28<>"",D28<>"",K28<>""),1,0) -> 0 | N28: =IF(L28=0,0,(L28/M24)) -> 0
F29: =IF(AND(B29<>"",D29<>""),IF(D29="Alta",VLOOKUP(B29,Tecnicas!$A$5:$D$58,2,0),IF(D29="Media",VLOOKUP(B29,Tecnicas!$A$5:$D$58,3,0),IF(D29="Baja",VLOOKUP(B29,Tecnicas!A7:D61,4,0)))),"") | J29: =IF(OR(B29="",D29=""),"",IF(K29="Altamente Desarrollada",5,IF(K29="Desarrollada",4,IF(K29="Medianamente Desarrollada",3,IF(K29="Poco Desarrollada",2,IF(K29="No Desarrollada",1,"")))))) | L29: =IF(J29<>"",IF(J29=5,8,IF(J29=4,6,IF(J29=3,4,IF(J29=2,2,IF(J29=1,0,""))))),0) -> 0 | M29: =IF(AND(B29<>"",D29<>"",K29<>""),1,0) -> 0 | N29: =IF(L29=0,0,(L29/M24)) -> 0
F30: =IF(AND(B30<>"",D30<>""),IF(D30="Alta",VLOOKUP(B30,Tecnicas!$A$5:$D$58,2,0),IF(D30="Media",VLOOKUP(B30,Tecnicas!$A$5:$D$58,3,0),IF(D30="Baja",VLOOKUP(B30,Tecnicas!A8:D62,4,0)))),"") | J30: =IF(OR(B30="",D30=""),"",IF(K30="Altamente Desarrollada",5,IF(K30="Desarrollada",4,IF(K30="Medianamente Desarrollada",3,IF(K30="Poco Desarrollada",2,IF(K30="No Desarrollada",1,"")))))) | L30: =IF(J30<>"",IF(J30=5,8,IF(J30=4,6,IF(J30=3,4,IF(J30=2,2,IF(J30=1,0,""))))),0) -> 0 | M30: =IF(AND(B30<>"",D30<>"",K30<>""),1,0) -> 0 | N30: =IF(L30=0,0,(L30/M24)) -> 0
B31: Total Competencias Técnicas del Puesto : | K31: =CONCATENATE(ROUND(N24,1),"%") -> 0%
B32: COMPETENCIAS CONDUCTUALES | D32: # Competencias: | F32: =M32 -> 0 | G32: Factor: | H32: 0.08 | L32: =IF(M32=6,SUM(L35:L40),0%) -> 0 | M32: =SUM(M35:M40) -> 0
B33: ESTOS CAMPOS DEBEN SER LLENADOS OBLIGATORIAMENTE :
B34: DESTREZA | D34: Relevancia | F34: Comportamiento Observable | I34: Frecuencia de Aplicación
B35: APRENDIZAJE CONTINUO | F35: =IF(AND(B35<>"",D35<>""),IF(D35="Alta",VLOOKUP(B35,Tecnicas!$A$5:$D$58,2,0),IF(D35="Media",VLOOKUP(B35,Tecnicas!$A$5:$D$58,3,0),IF(D35="Baja",VLOOKUP(B35,Tecnicas!A13:D67,4,0)))),"") | J35: =IF(OR(B35="",D35=""),"",IF(K35="Siempre",5,IF(K35="Frecuentemente",4,IF(K35="Alguna vez",3,IF(K35="Rara vez",2,IF(K35="Nunca",1,"")))))) | L35: =IF(J35=5,1.33,IF(J35=4,0.99,IF(J35=3,0.66,IF(J35=2,0.33,IF(J35=1,0,""))))) | M35: =IF(AND(D35<>"",K35<>""),1,0) -> 0
B36: CONOCIMIENTOS DEL ENTORNO ORGANIZACIONAL | F36: =IF(AND(B36<>"",D36<>""),IF(D36="Alta",VLOOKUP(B36,Tecnicas!$A$5:$D$58,2,0),IF(D36="Media",VLOOKUP(B36,Tecnicas!$A$5:$D$58,3,0),IF(D36="Baja",VLOOKUP(B36,Tecnicas!A14:D68,4,0)))),"") | J36: =IF(OR(B36="",D36=""),"",IF(K36="Siempre",5,IF(K36="Frecuentemente",4,IF(K36="Alguna vez",3,IF(K36="Rara vez",2,IF(K36="Nunca",1,"")))))) | L36: =IF(J36=5,1.33,IF(J36=4,0.99,IF(J36=3,0.66,IF(J36=2,0.33,IF(J36=1,0,""))))) | M36: =IF(AND(D36<>"",K36<>""),1,0) -> 0
B37: RELACIONES HUMANAS | F37: =IF(AND(B37<>"",D37<>""),IF(D37="Alta",VLOOKUP(B37,Tecnicas!$A$5:$D$58,2,0),IF(D37="Media",VLOOKUP(B37,Tecnicas!$A$5:$D$58,3,0),IF(D37="Baja",VLOOKUP(B37,Tecnicas!A15:D69,4,0)))),"") | J37: =IF(OR(B37="",D37=""),"",IF(K37="Siempre",5,IF(K37="Frecuentemente",4,IF(K37="Alguna vez",3,IF(K37="Rara vez",2,IF(K37="Nunca",1,"")))))) | L37: =IF(J37=5,1.33,IF(J37=4,0.99,IF(J37=3,0.66,IF(J37=2,0.33,IF(J37=1,0,""))))) | M37: =IF(AND(D37<>"",K37<>""),1,0) -> 0
B38: ACTITUD AL CAMBIO | F38: =IF(AND(B38<>"",D38<>""),IF(D38="Alta",VLOOKUP(B38,Tecnicas!$A$5:$D$58,2,0),IF(D38="Media",VLOOKUP(B38,Tecnicas!$A$5:$D$58,3,0),IF(D38="Baja",VLOOKUP(B38,Tecnicas!A16:D70,4,0)))),"") | J38: =IF(OR(B38="",D38=""),"",IF(K38="Siempre",5,IF(K38="Frecuentemente",4,IF(K38="Alguna vez",3,IF(K38="Rara vez",2,IF(K38="Nunca",1,"")))))) | L38: =IF(J38=5,1.33,IF(J38=4,0.99,IF(J38=3,0.66,IF(J38=2,0.33,IF(J38=1,0,""))))) | M38: =IF(AND(D38<>"",K38<>""),1,0) -> 0
B39: ORIENTACIÓN A LOS RESULTADOS | F39: =IF(AND(B39<>"",D39<>""),IF(D39="Alta",VLOOKUP(B39,Tecnicas!$A$5:$D$58,2,0),IF(D39="Media",VLOOKUP(B39,Tecnicas!$A$5:$D$58,3,0),IF(D39="Baja",VLOOKUP(B39,Tecnicas!A17:D71,4,0)))),"") | J39: =IF(OR(B39="",D39=""),"",IF(K39="Siempre",5,IF(K39="Frecuentemente",4,IF(K39="Alguna vez",3,IF(K39="Rara vez",2,IF(K39="Nunca",1,"")))))) | L39: =IF(J39=5,1.33,IF(J39=4,0.99,IF(J39=3,0.66,IF(J39=2,0.33,IF(J39=1,0,""))))) | M39: =IF(AND(D39<>"",K39<>""),1,0) -> 0
B40: ORIENTACIÓN DE SERVICIO | F40: =IF(AND(B40<>"",D40<>""),IF(D40="Alta",VLOOKUP(B40,Tecnicas!$A$5:$D$58,2,0),IF(D40="Media",VLOOKUP(B40,Tecnicas!$A$5:$D$58,3,0),IF(D40="Baja",VLOOKUP(B40,Tecnicas!A18:D72,4,0)))),"") | J40: =IF(OR(B40="",D40=""),"",IF(K40="Siempre",5,IF(K40="Frecuentemente",4,IF(K40="Alguna vez",3,IF(K40="Rara vez",2,IF(K40="Nunca",1,"")))))) | L40: =IF(J40=5,1.33,IF(J40=4,0.99,IF(J40=3,0.66,IF(J40=2,0.33,IF(J40=1,0,""))))) | M40: =IF(AND(D40<>"",K40<>""),1,0) -> 0
...

Sheet Tecnicas
A1: CATÁLOGO DE COMPETENCIAS TÉCNICAS DEL PUESTO
A3: DESTREZA HABILIDAD | B3: RELEVANCIA DEL COMPORTAMIENTO OBSERVABLE
B4: ALTA | C4: MEDIA | D4: BAJA
A5: Análisis de operaciones | B5: Identificar el sistema de control requerido por una nueva unidad organizacional | C5: Sugerir cambios en un programa de computación para que su uso resulte más fácil al usuario. | D5: Seleccionar un equipo para la oficina
A6: Comprensión escrita | B6: Lee y comprende documentos de alta complejidad. Elabora propuestas de solución o mejoramiento sobre la base del nivel de comprensión | C6: Lee y comprende documentos de complejidad media, y posteriormente presenta informes. | D6: Lee y comprende la información sencilla que se le presenta en forma escrita y realiza las acciones pertinentes que indican el nivel de comprensión.
A7: Comprensión oral | B7: Comprende las ideas presentadas en forma oral en las reuniones de trabajo y desarrolla propuestas en base a los requerimientos. | C7: Escucha y comprende los requerimientos de los usuario internos y externos y elabora informes. | D7: Escucha y comprende la información o disposiciones que se le provee y realiza las acciones pertinentes para el cumplimiento.
A8: Comprobación | B8: Realiza pruebas y ensayos de naturaleza compleja para comprobar si un nuevo sistema, equipo o procedimiento técnico - administrativo, funcionará correctamente. Identifica claramente los errores y propone los correctivos | C8: Enciende máquinas o equipos por primera vez para verificar su funcionamiento. Constata la calidad de los productos. | D8: Verifica el funcionamiento de máquinas o equipos, frecuentemente.
A9: Desarrollo estratégico de los recursos humanos | B9: Realiza una proyección de posibles necesidades de recursos humanos considerando distintos escenarios a largo plazo. Tiene un papel activo en la definición de las políticas en función del análisis estratégico. | C9: Utiliza herramientas existentes o nuevas en la organización para el desarrollo de los colaboradores en función de las estrategias de la organización. Promueve acciones de desarrollo. | D9: Aplica las herramientas de desarrollo disponibles. Define acciones para el desarrollo de las competencias críticas. Esporádicamente hace un seguimiento de las mismas.
A10: Destreza matemática | B10: Desarrolla un modelo matemático para simular y resolver problemas. | C10: Utiliza las matemáticas para realizar cálculos de complejidad media. (Ejemplo liquidaciones, conciliaciones bancarias, etc.) | D10: Contar dinero para entregar cambios.
A11: Detección de averías | B11: Detecta fallas en sistemas o equipos de alta complejidad de operación como por ejemplo, depurar el código de control de un nuevo sistema operativo. | C11: Identifica el circuito causante de una falla eléctrica o de equipos o sistemas de operación compleja. | D11: Busca la fuente que ocasiona errores en la operación de máquinas, automóviles y otros equipos de operación sencilla.
A12: Diseño de tecnología | B12: Crea nueva tecnología. | C12: Diseña los mecanismos de implementación de nuevas tecnologías que permiten mejorar la gestión de la organización. | D12: Rediseña el portal Web institucional, base de datos y otros para mejorar el acceso a la información.
A13: Expresión escrita | B13: Escribir documentos de complejidad alta, donde se establezcan parámetros que tengan impacto directo sobre el funcionamiento de una organización, proyectos u otros. Ejemplo (Informes de procesos legales, técnicos, administrativos) | C13: Escribir documentos de mediana complejidad, ejemplo (oficios, circulares) | D13: Escribir documentos sencillos en forma clara y concisa. Ejemplo (memorando)
A14: Expresión oral | B14: Expone programas, proyectos y otros ante las autoridades y personal de otras instituciones. | C14: Comunica información relevante. Organiza la información para que sea comprensible a los receptores. | D14: Comunica en forma clara y oportuna información sencilla.
A15: Generación de ideas | B15: Desarrolla planes, programas o proyectos alternativos para solucionar problemas estratégicos organizacionales. | C15: Desarrolla estrategias para la optimización de los recursos humanos, materiales y económicos. | D15: Encuentra procedimientos alternativos para apoyar en la entrega de productos o servicios a los usuarios.
A16: Habilidad analítica (análisis de prioridad, criterio lógico, sentido común) | B16: Realiza análisis lógicos para identificar los problemas fundamentales de la organización. | C16: Reconoce la información significativa, busca y coordina los datos relevantes para el desarrollo de programas y proyectos. | D16: Presenta datos estadísticos y/o financieros.
... A38: Selección de equipos | B38: Identifica el equipo necesario que debe adquirir una institución para cumplir con los planes, programas y proyectos. | C38: Escoge un nuevo programa informático para la automatización de ciertas actividades. | D38: Selecciona los instrumentos necesarios para una reunión de trabajo.
A40: CATÁLOGO DE COMPETENCIAS UNIVERSALES DEL PUESTO
A42: DESTREZA HABILIDAD | B42: RELEVANCIA DEL COMPORTAMIENTO OBSERVABLE
B43: ALTA | C43: MEDIA | D43: BAJA
A44: APRENDIZAJE CONTINUO | B44: Realiza trabajos de investigación que comparte con sus compañeros. Comparte sus conocimientos y experiencias actuando como agente de cambio y propagador de nuevas ideas y tecnologías. | C44: Mantiene su formación técnica. Realiza un gran esfuerzo por adquirir nuevas habilidades y conocimientos. | D44: Busca información sólo cuando la necesita, lee manuales, libros y otros, para aumentar sus conocimientos básicos.
A45: CONOCIMIENTOS DEL ENTORNO ORGANIZACIONAL | B45: Identifica las razones que motivan determinados comportamientos en los grupos de trabajo, los problemas de fondo de las unidades o procesos, oportunidades o fuerzas de poder que los afectan. | C45: Identifica, describe y utiliza las relaciones de poder e influencia existentes dentro de la institución, con un sentido claro de lo que es influir en la institución. | D45: Utiliza las normas, la cadena de mando y los procedimientos establecidos para cumplir con sus responsabilidades. Responde a requerimientos explícitos.
A46: RELACIONES HUMANAS | B46: Construye relaciones beneficiosas para el usuario externo y la institución, que le permiten alcanzar los objetivos organizacionales. Identifica y crea nuevas oportunidades en beneficio de la institución. | C46: Construye relaciones, tanto fuera como dentro de la institución que le proveen información. Establece un ambiente cordial con personas desconocidas, desde el primer encuentro | D46: Entabla relaciones a nivel laboral. Inicia y mantiene relaciones sociales con compañeros, usuarios y proveedores.
A47: ACTITUD AL CAMBIO | B47: Modifica las acciones para responder a los cambios organizacionales o de prioridades. Propone mejoras para la institución. | C47: Modifica su comportamiento para adaptarse a la situación o a las personas. Decide qué hacer en función de la situación. | D47: Aplica normas que dependen a cada situación o procedimientos para cumplir con sus responsabilidades
A48: ORIENTACIÓN A LOS RESULTADOS | B48: Realiza las acciones necesarias para cumplir con las metas propuestas. Desarrolla o modifica procesos organizacionales que contribuyan a mejorar la eficiencia. | C48: Modifica los métodos de trabajo para conseguir mejoras. Actúa para lograr y superar niveles de desempeño y plazos establecidos. | D48: Realiza bien o correctamente su trabajo.
A49: ORIENTACIÓN DE SERVICIO | B49: Demuestra interés en atender a los usuarios internos y externos con rapidez, diagnostica correctamente la necesidad y plantea soluciones adecuadas. | C49: Identifica las necesidades del usuario interno o externo. | D49: Actúa a partir de los requerimientos de los usuarios ofreciendo respuestas estandarizadas a sus demandas.
A51: CATÁLOGO DE TRABAJO EN EQUIPO E INICIATIVA DEL PUESTO
A53: DESTREZA HABILIDAD | B53: RELEVANCIA DEL COMPORTAMIENTO OBSERVABLE
B54: ALTA | C54: MEDIA | D54: BAJA
A55: TRABAJO EN EQUIPO | B55: Crea un buen clima de trabajo y espíritu de cooperación. Resuelve los conflictos que se puedan producir dentro del equipo. Se considera que es un referente en el manejo de equipos de trabajo. Promueve de trabajo en equipo con otra áreas de la organización. | C55: Promueve la colaboración de los distintos integrantes del equipos. Valora sinceramente las ideas y experiencias de los demás. | D55: Coopera. Participa activamente en el equipo, apoya las decisiones. Realiza la parte del trabajo que le corresponde. Como miembro de un equipo, mantiene informados a los demás. Comparte información.
A56: INICIATIVA | B56: Se anticipa a las situaciones con una visión a largo plazo. | C56: Se adelanta y se prepara para los acontecimientos que pueden ocurrir a corto plazo. Crea oportunidades o minimiza problemas potenciales. Aplica distintas formas de trabajo con una visión de mediano plazo. | D56: Reconoce las oportunidades o problemas del momento. Cuestiona las formas convencionales de trabajar.
A57: LIDERAZGO | B57: Alto desarrollo de los talentos y motivación en su equipo de trabajo para generar comunicación, confianza y compromiso a través del ejemplo y servicio para el logro de objetivos comunes. | C57: Mediano desarrollo de los talentos y motivación en su equipo de trabajo para generar comunicación, confianza y compromiso a través del ejemplo y servicio para el logro de objetivos comunes. | D57: Poco desarrollo de los talentos y motivación en su equipo de trabajo para generar comunicación, confianza y compromiso a través del ejemplo y servicio para el logro de objetivos comunes.
A60: IMPORTANTE | B60: UNA VEZ INGRESADO LAS COMPETENCIAS QUE USTED REQUIERA VUELVA A LA PESTAÑA EVAL01 :
A80: DESTREZA HABILIDAD | B80: RELEVANCIA DEL COMPORTAMIENTO OBSERVABLE
B81: ALTA | C81: MEDIA | D81: BAJA
A82: Aprendizaje continuo | B82: Realiza trabajos de investigación que comparte con sus compañeros. Comparte sus conocimientos y experiencias actuando como agente de cambio y propagador de nuevas ideas y tecnologías. | C82: Mantiene su formación técnica. Realiza un gran esfuerzo por adquirir nuevas habilidades y conocimientos. | D82: Busca información sólo cuando la necesita, lee manuales, libros y otros, para aumentar sus conocimientos básicos.
A83: Conocimiento del entrono organizacional | B83: Identifica las razones que motivan determinados comportamientos en los grupos de trabajo, los problemas de fondo de las unidades o procesos, oportunidades o fuerzas de poder que los afectan. | C83: Identifica, describe y utiliza las relaciones de poder e influencia existentes dentro de la institución, con un sentido claro de lo que es influir en la institución. | D83: Utiliza las normas, la cadena de mando y los procedimientos establecidos para cumplir con sus responsabilidades. Responde a los requerimientos explícitos.
A84: Relaciones Humanas | B84: Construye relaciones beneficiosas para el usuario externo y la institución, que le permiten alcanzar los objetivos organizacionales. Identifica y crea nuevas oportunidades en beneficio de la institución. | C84: Construye relaciones, tanto dentro como fuera de la institución que le proveen información. Establece un ambiente cordial con personas desconocidas, desde el primer encuentro. | D84: Entabla relaciones a nivel laboral. Inicia y mantiene relaciones sociales con compañeros, usuarios y proveedores.
A85: Actitud al Cambio | B85: Modifica las acciones para responder a los cambios organizacionales o de prioridades. Propone mejoras para la organización. | C85: Modifica su comportamiento para adaptarse a la situación o a las personas. Decide qué hacer en función de la situación. | D85: Aplica normas que dependen a cada situación o procedimientos para cumplir con sus responsabilidades.
A86: Orientación a los resultados | B86: Realiza las acciones necesarias para cumplir con las metas propuestas. Desarrolla o modifica procesos organizacionales que contribuyan a mejorar la eficiencia. | C86: Modifica los métodos de trabajo para conseguir mejoras. Actúa para lograr y superar niveles de desempeño y plazos establecidos. | D86: Realiza bien o correctamente su trabajo.
A87: Orientación de servicio | B87: Demuestra interés en atender a los usuarios internos o externos con rapidez, diagnóstica correctamente la necesidad y plantea soluciones adecuadas. | C87: Identifica las necesidades del usuario interno o externo | D87: Actúa a partir de los requerimientos de los usuarios ofreciendo respuestas estandarizadas a sus demandas.
...

Sheet NOTA
A1: PROTEGER CELDAS
A2: Seleccionar todo click en celda en blanco entre el numero de fila y letra de columna
A3: Sobre cualquier celda, click derecho, “Formato de celda - Protección celda – visto en Protegida y Ocultar fórmula
A4: Señalar celdas a quitar protección, click derecho, “Formato de celda - Protección celda – visto en Protegida y Ocultar fórmula
A6: Para que la protección de celdas surta efecto es necesario PROTEGER HOJA
A7: “Herramientas – Proteger hoja – con visto solamente Seleccionar celdas sin proteger”
A8: Ingresar contraseña

Sheet Hoja6
A1: Alta
A2: Media
A3: Baja
A5: Altamente Desarrollada
A6: Desarrollada
A7: Medianamente Desarrollada
A8: Poco Desarrollada
A9: No Desarrollada
A11: Siempre
A12: Frecuentemente
A13: Alguna vez
A14: Rara vez
A15: Nunca
A17: Sobresaliente | C17: SI
A18: Muy Bueno | C18: NO
A19: Bueno
A20: Regular
A21: Insuficiente
