Workbook

Sheet FORMATO DE PERMISOS Y VACACIONE
A2: FORMULARIO DE PERMISOS | J2: CEDULA DE IDENTIDAD
A3: NOMBRE DEL SERVIDOR: | C3: =VLOOKUP($J$3,Hoja2!$A$3:$L$120,2,0) -> Norma Arcos | E3: DEPARTAMENTO: | G3: =VLOOKUP($J$3,Hoja2!$A$3:$L$120,3,0) -> Dirección de Tecnologías de la Información | J3: 1719235432
A4: CEDULA: | C4: =J3 -> 1719235432 | E4: FECHA DE GENERACIÓN: | G4: =NOW() -> 45978.638 | J4: INGRESAR CEDULA SIN GUIONES EN EL CAMPO AMARILLO
A5: PERMISO POR HORAS: | D5: PERMISO POR DÍAS/ VACACIONES | G5: TIPO DE PERMISO | N5: 0.35416667
A6: FECHA: | B6: 45978 | D6: SALDO DE VACACIONES AL 31/10/2025 | E6: =VLOOKUP($J$3,Hoja2!$A$3:$L$120,9,0) -> 4 | F6: días laborables | G6: PERSONAL: | H6: X | N6: 0.375
A7: HORA DE SALIDA: | B7: 0.64583333 | D7: DESDE: | G7: CALAMIDAD DOMÉSTICA:
A8: HORA DE RETORNO: | B8: 0.70833333 | D8: HASTA: | G8: ENFERMEDAD/CITA MÉDICA:
A9: TOTAL HORAS DE PERMISO: | B9: =B8-B7 -> 0.0625 | D9: TOTAL DÍAS DE PERMISO: | E9: =NETWORKDAYS(E7,E8) -> 0 | F9: días laborables | G9: ASUNTOS INSTITUCIONALES
A10: SOLICITANTE | C10: AUTORIZACION | F10: REGISTRO | N10: 0.45833333
N11: 0.47916667
A12: =C3 -> Norma Arcos | C12: =VLOOKUP($J$3,Hoja2!$A$3:$L$120,4,0) -> Dirección de Tecnologías de la Información | F12: Cristina Pucha | N12: 0.5
A13: SERVIDOR(A) | C13: DIRECTOR(A) | F13: DIRECCION ADMINISTRATIVA | N13: 0.52083333
A14: NOTA: Los permisos autorizará únicamente el Director o Jefe de área | F14: Departamento Administrativo | N14: 0.54166667
F15: Formulario # 014 | N15: 0.5625
A16: OBSERVACIONES:
N21: 0.58333333
N22: 0.60416667
N23: 0.625
A24: FORMULARIO DE PERMISOS | N24: 0.64583333
A25: NOMBRE DEL SERVIDOR: | C25: =C3 -> Norma Arcos | E25: DEPARTAMENTO: | G25: =G3 -> Dirección de Tecnologías de la Información | N25: 0.66666667
A26: CEDULA: | C26: =J3 -> 1719235432 | E26: FECHA DE GENERACIÓN: | G26: =NOW() -> 45978.638 | N26: 0.6875
A27: PERMISO POR HORAS: | D27: PERMISO POR DÍAS/ VACACIONES | G27: TIPO DE PERMISO | N27: 0.70833333
A28: FECHA: | B28: =IF(B6=0," ",B6) -> 45978 | D28: =D6 -> SALDO DE VACACIONES AL 31/10/2025 | E28: =VLOOKUP($J$3,Hoja2!$A$3:$L$120,9,0) -> 4 | F28: días laborables | G28: PERSONAL: | H28: =IF(H6=0," ",H6) -> X | N28: 0.375
A29: HORA DE SALIDA: | B29: =B7 -> 0.64583333 | D29: DESDE: | E29: =IF(E7=0," ",E7) | G29: CALAMIDAD DOMÉSTICA: | H29: =IF(H7=0," ",H7)
A30: HORA DE RETORNO: | B30: =B8 -> 0.70833333 | D30: HASTA: | E30: =IF(E8=0," ",E8) | G30: ENFERMEDAD/CITA MÉDICA: | H30: =IF(H8=0," ",H8)
A31: TOTAL HORAS DE PERMISO: | B31: =B9 -> 0.0625 | D31: TOTAL DÍAS DE PERMISO: | E31: =E9 -> 0 | F31: días laborables | G31: ASUNTOS INSTITUCIONALES | H31: =IF(H9=0," ",H9)
A32: SOLICITANTE | C32: AUTORIZACION | F32: REGISTRO
A34: =C25 -> Norma Arcos | C34: =C12 -> Dirección de Tecnologías de la Información | F34: =F12 -> Cristina Pucha
A35: SERVIDOR(A) | C35: DIRECTOR(A) | F35: DIRECCION ADMINISTRATIVA
A36: NOTA: Los permisos autorizará únicamente el Director o Jefe de área | F36: Departamento Administrativo
F37: Formulario # 014
A38: OBSERVACIONES: | B38: =B16 -> 0
A39: =IF(A17=0," ",A17)

Sheet Hoja2
F1: PERMISOS | I1: VACACIONES
A2: Cédula de Ciudadanía | B2: Servidor | C2: Dirección a la que pertenece | D2: Dirección que autoriza | F2: Días | G2: Horas | H2: Minutos | I2: Días Laborables | J2: Horas | K2: Minutos | L2: días calendario
A3: 1713418190 | B3: Marilin Salgado | C3: Dirección Administrativa | D3: Dirección Administrativa | F3: =+'[1]Marilin Salgado'!D4 -> 139 | G3: =+'[1]Marilin Salgado'!E4 -> 3 | H3: =+'[1]Marilin Salgado'!F4 -> 20 | I3: =+'[1]Marilin Salgado'!D5 -> 18 | J3: =+'[1]Marilin Salgado'!E5 -> 3 | K3: =+'[1]Marilin Salgado'!F5 -> 20 | L3: =+'[1]Marilin Salgado'!G5 -> 24.545455
A4: 1003241583 | B4: Wilson Lechón | C4: Dirección de Gestión Ambiental | D4: Dirección de Gestión Ambiental | F4: =+'[1]Wilson Lechon'!D5 -> 144 | G4: =+'[1]Wilson Lechon'!E5 -> 7 | H4: =+'[1]Wilson Lechon'!F5 -> 14 | I4: =+'[1]Wilson Lechon'!D6 -> 0 | J4: =+'[1]Wilson Lechon'!E6 -> 6 | K4: =+'[1]Wilson Lechon'!F6 -> 6 | L4: =+'[1]Wilson Lechon'!G6 -> 0
A5: 1713586129 | B5: Johanna Portilla | C5: Dirección Administrativa | D5: Dirección Administrativa | F5: =+'[1]Johanna Portilla'!D4 -> 138 | G5: =+'[1]Johanna Portilla'!E4 -> 6 | H5: =+'[1]Johanna Portilla'!F4 -> 42 | I5: =+'[1]Johanna Portilla'!D5 -> 21 | J5: =+'[1]Johanna Portilla'!E5 -> 3 | K5: =+'[1]Johanna Portilla'!F5 -> 58 | L5: =+'[1]Johanna Portilla'!G5 -> 28.636364
A6: 1102049705 | B6: Mabel Córdova | C6: Dirección Ejecutiva | D6: Dirección Ejecutiva | F6: =+'[1]Mabel Córdova'!D4 -> 145 | G6: =+'[1]Mabel Córdova'!E4 -> 5 | H6: =+'[1]Mabel Córdova'!F4 -> 56 | I6: =+'[1]Mabel Córdova'!D5 -> 27 | J6: =+'[1]Mabel Córdova'!E5 -> 4 | K6: =+'[1]Mabel Córdova'!F5 -> 44 | L6: =+'[1]Mabel Córdova'!G5 -> 36.818182
A7: 1705685657 | B7: José Andrade | C7: Dirección de Vialidad, Infraestructura, Riego y Drenaje | D7: Dirección de Vialidad, Infraestructura, Riego y Drenaje | F7: =+'[1]José Andrade'!D5 -> 150 | G7: =+'[1]José Andrade'!E5 -> 7 | H7: =+'[1]José Andrade'!F5 -> 49 | I7: =+'[1]José Andrade'!D6 -> 20 | J7: =+'[1]José Andrade'!E6 -> 1 | K7: =+'[1]José Andrade'!F6 -> 31 | L7: =+'[1]José Andrade'!G6 -> 27.272727
A8: 1714728738 | B8: Jeanine Alvear | C8: Dirección de Fomento Productivo | D8: Dirección de Gestión Ambiental | F8: ='[1]Jeanine Alvear'!D6 -> 161 | G8: ='[1]Jeanine Alvear'!E6 -> 0 | H8: ='[1]Jeanine Alvear'!F6 -> 28 | I8: ='[1]Jeanine Alvear'!D7 -> 21 | J8: ='[1]Jeanine Alvear'!E7 -> 4 | K8: ='[1]Jeanine Alvear'!F7 -> 52 | L8: ='[1]Jeanine Alvear'!G7 -> 28.636364
A9: 1719055830 | B9: María José Almache | C9: Dirección de Fomento Productivo | D9: Dirección de Fomento Productivo | F9: =+'[1]María José Almache'!D5 -> 146 | G9: =+'[1]María José Almache'!E5 -> 0 | H9: =+'[1]María José Almache'!F5 -> 18 | I9: =+'[1]María José Almache'!D6 -> 13 | J9: =+'[1]María José Almache'!E6 -> 1 | K9: =+'[1]María José Almache'!F6 -> 2 | L9: =+'[1]María José Almache'!G6 -> 17.727273
A10: 1717498396 | B10: Paola Cadena | C10: Dirección de Proyectos, Seguimiento y Monitoreo | D10: Dirección de Proyectos, Seguimiento y Monitoreo | F10: =+'[1]Paola Cadena'!D4 -> 125 | G10: =+'[1]Paola Cadena'!E4 -> 6 | H10: =+'[1]Paola Cadena'!F4 -> 50 | I10: =+'[1]Paola Cadena'!D5 -> 20 | J10: =+'[1]Paola Cadena'!E5 -> 3 | K10: =+'[1]Paola Cadena'!F5 -> 50 | L10: =+'[1]Paola Cadena'!G5 -> 27.272727
A11: 1711331668 | B11: Gabriela Banda | C11: Dirección de Asesoría Jurídica | D11: Dirección de Asesoría Jurídica | F11: =+'[1]Gabriela Banda'!D4 -> 89 | G11: =+'[1]Gabriela Banda'!E4 -> 3 | H11: =+'[1]Gabriela Banda'!F4 -> 31 | I11: =+'[1]Gabriela Banda'!D5 -> 15 | J11: =+'[1]Gabriela Banda'!E5 -> 4 | K11: =+'[1]Gabriela Banda'!F5 -> 45 | L11: =+'[1]Gabriela Banda'!G5 -> 20.454545
A12: 501692511 | B12: Antonieta Araujo | C12: Dirección Administrativa | D12: Dirección Administrativa | F12: =+'[1]Antonieta Araujo'!D6 -> 122 | G12: =+'[1]Antonieta Araujo'!E6 -> 0 | H12: =+'[1]Antonieta Araujo'!F6 -> 31 | I12: =+'[1]Antonieta Araujo'!D7 -> 28 | J12: =+'[1]Antonieta Araujo'!E7 -> 3 | K12: =+'[1]Antonieta Araujo'!F7 -> 29 | L12: =+'[1]Antonieta Araujo'!G7 -> 38.181818
A13: 1715594287 | B13: Jenny Carrillo | C13: Dirección de Proyectos, Seguimiento y Monitoreo | D13: Dirección de Planificación | F13: =+'[1]Jenny Carrillo'!D4 -> 127 | G13: =+'[1]Jenny Carrillo'!E4 -> 0 | H13: =+'[1]Jenny Carrillo'!F4 -> 4 | I13: =+'[1]Jenny Carrillo'!D5 -> 23 | J13: =+'[1]Jenny Carrillo'!E5 -> 1 | K13: =+'[1]Antonieta Araujo'!F8 -> 0 | L13: =+'[1]Jenny Carrillo'!G5 -> 31.363636
A14: 401075031 | B14: Viviana De la Cadena | C14: Dirección de Cooperación | D14: Dirección de Cooperación | F14: =+'[1]Viviana de la Cadena'!D6 -> 158 | G14: =+'[1]Viviana de la Cadena'!E6 -> 4 | H14: =+'[1]Viviana de la Cadena'!F6 -> 31 | I14: =+'[1]Viviana de la Cadena'!D7 -> 18 | J14: =+'[1]Viviana de la Cadena'!E7 -> 0 | K14: =+'[1]Viviana de la Cadena'!F7 -> 49 | L14: =+'[1]Viviana de la Cadena'!G7 -> 24.545455
A15: 502811573 | B15: Lorena Erazo | C15: Dirección de Vialidad, Infraestructura, Riego y Drenaje | D15: Dirección de Vialidad, Infraestructura, Riego y Drenaje | F15: =+'[1]Lorena Erazo'!D6 -> 134 | G15: =+'[1]Lorena Erazo'!E6 -> 0 | H15: =+'[1]Lorena Erazo'!F6 -> 36 | I15: =+'[1]Lorena Erazo'!D7 -> 39 | J15: =+'[1]Lorena Erazo'!E7 -> 4 | K15: =+'[1]Lorena Erazo'!F7 -> 44 | L15: =+'[1]Lorena Erazo'!G7 -> 53.181818
A16: 1714505433 | B16: Victoria Guerra | C16: Dirección Financiera | D16: Dirección Financiera | F16: =+'[1]Victoria Guerra'!D5 -> 154 | G16: =+'[1]Victoria Guerra'!E5 -> 3 | H16: =+'[1]Victoria Guerra'!F5 -> 21 | I16: =+'[1]Victoria Guerra'!D6 -> 31 | J16: =+'[1]Victoria Guerra'!E6 -> 7 | K16: =+'[1]Victoria Guerra'!F6 -> 19 | L16: =+'[1]Victoria Guerra'!G6 -> 42.272727
A17: 1720496791 | B17: Renán Guerrero | C17: Dirección de Tecnologías de la Información | D17: Direccion Ejecutiva | F17: =+'[1]Renan Guerrero'!D4 -> 108 | G17: =+'[1]Renan Guerrero'!E4 -> 4 | H17: =+'[1]Renan Guerrero'!F4 -> 52 | I17: =+'[1]Renan Guerrero'!D5 -> 33 | J17: =+'[1]Renan Guerrero'!E5 -> 1 | K17: =+'[1]Renan Guerrero'!F5 -> 48 | L17: =+'[1]Renan Guerrero'!G5 -> 45
A18: 1103992416 | B18: Henrry Guzmán | C18: Dirección de Gestión Ambiental | D18: Dirección Ejecutiva | F18: =+'[1]Henrry Guzman'!D4 -> 140 | G18: =+'[1]Henrry Guzman'!E4 -> 0 | H18: =+'[1]Henrry Guzman'!F4 -> 30 | I18: =+'[1]Henrry Guzman'!D5 -> 23 | J18: =+'[1]Henrry Guzman'!E5 -> 0 | K18: =+'[1]Henrry Guzman'!F5 -> 50 | L18: =+'[1]Henrry Guzman'!G5 -> 31.363636
A19: 401030523 | B19: Lenin Illapa | C19: Dirección de Tecnologías de la Información | D19: Dirección de Tecnologías de la Información | F19: =+'[1]Lenin Illapa'!D4 -> 136 | G19: =+'[1]Lenin Illapa'!E4 -> 5 | H19: =+'[1]Lenin Illapa'!F4 -> 25 | I19: =+'[1]Lenin Illapa'!D5 -> 8 | J19: =+'[1]Lenin Illapa'!E5 -> 5 | K19: =+'[1]Lenin Illapa'!F5 -> 15 | L19: =+'[1]Lenin Illapa'!G5 -> 10.909091
A20: 1802921617 | B20: María Elena Llerena | C20: Dirección de Fomento Productivo | D20: Direcció de Fomento Productivo | F20: =+'[1]Maria Elena Llerena'!D4 -> 139 | G20: =$F$20 -> 139 | H20: =$F$20 -> 139 | I20: =+'[1]Maria Elena Llerena'!D5 -> 9 | J20: =+'[1]Maria Elena Llerena'!E5 -> 6 | K20: =+'[1]Maria Elena Llerena'!F5 -> 12 | L20: =+'[1]Maria Elena Llerena'!G5 -> 12.272727
A21: 801553215 | B21: Verónica Marchán | C21: Dirección Financiera | D21: Dirección Financiera | F21: =+'[1]Verónica Marchan'!D4 -> 140 | G21: =+'[1]Verónica Marchan'!E4 -> 4 | H21: =+'[1]Verónica Marchan'!F4 -> 37 | I21: =+'[1]Verónica Marchan'!D5 -> 24 | J21: =+'[1]Verónica Marchan'!E5 -> 6 | K21: =+'[1]Verónica Marchan'!F5 -> 3 | L21: =+'[1]Verónica Marchan'!G5 -> 32.727273
A22: 1724351406 | B22: Byron Mera | C22: Dirección Administrativa | D22: Dirección Administrativa | F22: =+'[1]Byron Mera'!D4 -> 143 | G22: =+'[1]Byron Mera'!E4 -> 6 | H22: =+'[1]Byron Mera'!F4 -> 42 | I22: =+'[1]Byron Mera'!D5 -> 7 | J22: =+'[1]Byron Mera'!E5 -> 5 | K22: =+'[1]Byron Mera'!F5 -> 18 | L22: =+'[1]Byron Mera'!G5 -> 9.5454545
A23: 1712911468 | B23: Mónica Muñoz | C23: Dirección Ejecutiva | D23: Dirección Ejecutiva | F23: =+'[1]Mónica Muñoz'!D5 -> 166 | G23: =+'[1]Mónica Muñoz'!E5 -> 3 | H23: =+'[1]Mónica Muñoz'!F5 -> 24 | I23: =+'[1]Mónica Muñoz'!D6 -> 19 | J23: =+'[1]Mónica Muñoz'!E6 -> 0 | K23: =+'[1]Mónica Muñoz'!F6 -> 36 | L23: =+'[1]Mónica Muñoz'!G6 -> 25.909091
A24: 1712610953 | B24: Sandra Negrete | C24: Dirección Administrativa | D24: Dirección Administrativa | F24: =+'[1]Sandra Negrete'!D4 -> 134 | G24: =+'[1]Sandra Negrete'!E4 -> 4 | H24: =+'[1]Sandra Negrete'!F4 -> 28 | I24: =+'[1]Sandra Negrete'!D5 -> 15 | J24: =+'[1]Sandra Negrete'!E5 -> 7 | K24: =+'[1]Sandra Negrete'!F5 -> 32 | L24: =+'[1]Sandra Negrete'!G5 -> 20.454545
A25: 1713427548 | B25: Joe Ortiz | C25: Dirección de Tecnologías de la Información | D25: Dirección de Tecnologías de la Información | F25: =+'[1]Joe Ortiz'!D5 -> 118 | G25: =+'[1]Joe Ortiz'!E5 -> 1 | H25: =+'[1]Joe Ortiz'!F5 -> 49 | I25: =+'[1]Joe Ortiz'!D6 -> 25 | J25: =+'[1]Joe Ortiz'!E6 -> 2 | K25: =+'[1]Joe Ortiz'!F6 -> 11 | L25: =+'[1]Joe Ortiz'!G6 -> 34.090909
A26: 1720669561 | B26: Cristina Pucha | C26: Dirección Administrativa | D26: Dirección Administrativa | F26: =+'[1]Cristina Pucha'!D4 -> 142 | G26: =+'[1]Cristina Pucha'!E4 -> 6 | H26: =+'[1]Cristina Pucha'!F4 -> 31 | I26: =+'[1]Cristina Pucha'!D5 -> 18 | J26: =+'[1]Cristina Pucha'!E5 -> 4 | K26: =+'[1]Cristina Pucha'!F5 -> 9 | L26: =+'[1]Cristina Pucha'!G5 -> 24.545455
A27: 401077276 | B27: María Dolores Ponce | C27: Dirección de Comunicación | D27: Dirección de Comunicación | F27: =+'[1]María Dolores Ponce'!D4 -> 136 | G27: =+'[1]María Dolores Ponce'!E4 -> 1 | H27: =+'[1]María Dolores Ponce'!F4 -> 10 | I27: =+'[1]María Dolores Ponce'!D5 -> 16 | J27: =+'[1]María Dolores Ponce'!E5 -> 0 | K27: =+'[1]María Dolores Ponce'!F5 -> 10 | L27: =+'[1]María Dolores Ponce'!G5 -> 21.818182
A28: 801780479 | B28: Teresa Rea | C28: Dirección de Comunicación | D28: Dirección de Comunicación | F28: =+'[1]Teresa Rea'!D4 -> 101 | G28: =+'[1]Teresa Rea'!E4 -> 6 | H28: =+'[1]Teresa Rea'!F4 -> 26 | I28: =+'[1]Teresa Rea'!D5 -> 44 | J28: =+'[1]Teresa Rea'!E5 -> 4 | K28: =+'[1]Teresa Rea'!F5 -> 14 | L28: =+'[1]Teresa Rea'!G5 -> 60
A29: 501879373 | B29: Idilia Reinoso | C29: Dirección de Asesoría Jurídica | D29: Dirección de Asesoría Jurídica | F29: =+'[1]Idilia Reinoso'!D4 -> 144 | G29: =+'[1]Idilia Reinoso'!E4 -> 2 | H29: =+'[1]Idilia Reinoso'!F4 -> 17 | I29: =+'[1]Idilia Reinoso'!D5 -> 14 | J29: =+'[1]Idilia Reinoso'!E5 -> 0 | K29: =+'[1]Idilia Reinoso'!F5 -> 23 | L29: =+'[1]Idilia Reinoso'!G5 -> 19.090909
A30: 603200544 | B30: Fabián Romero | C30: Dirección de Vialidad, Infraestructura, Riego y Drenaje | D30: Dirección de Vialidad, Infraestructura, Riego y Drenaje | F30: =+'[1]Fabian Romero'!D4 -> 130 | G30: =+'[1]Fabian Romero'!E4 -> 5 | H30: =+'[1]Fabian Romero'!F4 -> 29 | I30: =+'[1]Fabian Romero'!D5 -> 9 | J30: =+'[1]Fabian Romero'!E5 -> 3 | K30: =+'[1]Fabian Romero'!F5 -> 51 | L30: =+'[1]Fabian Romero'!G5 -> 12.272727
A31: 703331702 | B31: Darwin Ruilova | C31: Dirección de Asesoría Jurídica | D31: Dirección de Asesoría Jurídica | F31: =+'[1]Darwin Ruilova'!D4 -> 108 | G31: =+'[1]Darwin Ruilova'!E4 -> 0 | H31: =+'[1]Darwin Ruilova'!F4 -> 33 | I31: =+'[1]Darwin Ruilova'!D5 -> 44 | J31: =+'[1]Darwin Ruilova'!E5 -> 4 | K31: =+'[1]Darwin Ruilova'!F5 -> 47 | L31: =+'[1]Darwin Ruilova'!G5 -> 60
A32: 1717608903 | B32: Mario Sáenz | C32: Unidad de Gestión Social / Dirección Administrativa | D32: Unidad de Gestión Social / Dirección Administrativa | F32: =+'[1]Mario Saenz'!D4 -> 110 | G32: =+'[1]Mario Saenz'!E4 -> 5 | H32: =+'[1]Mario Saenz'!F4 -> 45 | I32: =+'[1]Mario Saenz'!D5 -> 39 | J32: =+'[1]Mario Saenz'!E5 -> 3 | K32: =+'[1]Mario Saenz'!F5 -> 35 | L32: =+'[1]Mario Saenz'!G5 -> 53.181818
A33: 1716068398 | B33: David Sánchez | C33: Dirección de Planificación | D33: Dirección de Planificación | F33: =+'[1]David Sánchez'!D4 -> 138 | G33: =+'[1]David Sánchez'!E4 -> 2 | H33: =+'[1]David Sánchez'!F4 -> 30 | I33: =+'[1]David Sánchez'!D5 -> 28 | J33: =+'[1]David Sánchez'!E5 -> 1 | K33: =+'[1]David Sánchez'!F5 -> 30 | L33: =+'[1]David Sánchez'!G5 -> 38.181818
A34: 1714014055 | B34: María Toapanta | C34: Dirección Administrativa | D34: Dirección Administrativa | F34: =+'[1]María Toapanta'!D4 -> 131 | G34: =+'[1]María Toapanta'!E4 -> 5 | H34: =+'[1]María Toapanta'!F4 -> 51 | I34: =+'[1]María Toapanta'!D5 -> 11 | J34: =+'[1]María Toapanta'!E5 -> 4 | K34: =+'[1]María Toapanta'!F5 -> 49 | L34: =+'[1]María Toapanta'!G5 -> 15
A35: 1307867034 | B35: Lucrecia Torres | C35: Dirección Ejecutiva | D35: Dirección de Planificación | F35: =+'[1]Lucrecia Torres'!D5 -> 140 | G35: =+'[1]Lucrecia Torres'!E5 -> 0 | H35: =+'[1]Lucrecia Torres'!F5 -> 14 | I35: =+'[1]Lucrecia Torres'!D6 -> 34 | J35: =+'[1]Lucrecia Torres'!E6 -> 6 | K35: =+'[1]Lucrecia Torres'!F6 -> 26 | L35: =+'[1]Lucrecia Torres'!G6 -> 46.363636
A36: 1716936529 | B36: Katty Toscano | C36: Dirección de Comunicación | D36: Dirección de Comunicación | F36: =+'[1]Katty Toscano'!D5 -> 150 | G36: =+'[1]Katty Toscano'!E5 -> 7 | H36: =+'[1]Katty Toscano'!F5 -> 11 | I36: =+'[1]Katty Toscano'!D6 -> 13 | J36: =+'[1]Katty Toscano'!E6 -> 6 | K36: =+'[1]Katty Toscano'!F6 -> 9 | L36: =+'[1]Katty Toscano'!G6 -> 17.727273
A37: 1600325292 | B37: Natalia Valverde | C37: Dirección Administrativa | D37: Dirección Administrativa | F37: =+'[1]Natalia Valverde'!D5 -> 96 | G37: =+'[1]Natalia Valverde'!E5 -> 3 | H37: =+'[1]Natalia Valverde'!F5 -> 51 | I37: =+'[1]Natalia Valverde'!D6 -> 33 | J37: =+'[1]Natalia Valverde'!E6 -> 2 | K37: =+'[1]Natalia Valverde'!F6 -> 49 | L37: =+'[1]Natalia Valverde'!G6 -> 45
A38: 1500871478 | B38: Alondra Yépez | C38: Unidad de Gestión Social / Dirección Administrativa | D38: Unidad de Gestión Social / Dirección Administrativa | F38: =+'[1]Alondra Yepez'!D4 -> 132 | G38: =+'[1]Alondra Yepez'!E4 -> 5 | H38: =+'[1]Alondra Yepez'!F4 -> 15.166667 | I38: =+'[1]Alondra Yepez'!D5 -> 7 | J38: =+'[1]Alondra Yepez'!E5 -> 5 | K38: =+'[1]Alondra Yepez'!F5 -> 24.833333 | L38: =+'[1]Alondra Yepez'!G5 -> 9.5454545
A39: 704159847 | B39: Andrés Zambrano | C39: Dirección de Asesoría Jurídica | D39: Dirección de Asesoría Jurídica | F39: =+'[1]Andrés Zambrano'!D5 -> 121 | G39: =+'[1]Andrés Zambrano'!E5 -> 6 | H39: =+'[1]Andrés Zambrano'!F5 -> 43 | I39: =+'[1]Andrés Zambrano'!D6 -> 26 | J39: =+'[1]Andrés Zambrano'!E6 -> 7 | K39: =+'[1]Andrés Zambrano'!F6 -> 57 | L39: =+'[1]Andrés Zambrano'!G6 -> 35.454545
A40: 1713851416 | B40: Ana Zambrano | C40: Dirección Administrativa | D40: Dirección Administrativa | F40: =+'[1]Ana Zambrano'!D4 -> 147 | G40: =+'[1]Ana Zambrano'!E4 -> 6 | H40: =+'[1]Ana Zambrano'!F4 -> 50.09375 | I40: =+'[1]Ana Zambrano'!D5 -> 7 | J40: =+'[1]Ana Zambrano'!E5 -> 3 | K40: =+'[1]Ana Zambrano'!F5 -> 49.90625 | L40: =+'[1]Ana Zambrano'!G5 -> 9.5454545
...
